[2024-05-01T14:20:07.638+0000] {local_task_job_runner.py:120} INFO - ::group::Pre task execution logs
[2024-05-01T14:20:07.660+0000] {taskinstance.py:2073} INFO - Dependencies all met for dep_context=non-requeueable deps ti=<TaskInstance: create_vehicle_tables.create_airflow_db_task manual__2024-05-01T14:15:00.135769+00:00 [queued]>
[2024-05-01T14:20:07.667+0000] {taskinstance.py:2073} INFO - Dependencies all met for dep_context=requeueable deps ti=<TaskInstance: create_vehicle_tables.create_airflow_db_task manual__2024-05-01T14:15:00.135769+00:00 [queued]>
[2024-05-01T14:20:07.667+0000] {taskinstance.py:2303} INFO - Starting attempt 2 of 5
[2024-05-01T14:20:07.710+0000] {taskinstance.py:2327} INFO - Executing <Task(PythonOperator): create_airflow_db_task> on 2024-05-01 14:15:00.135769+00:00
[2024-05-01T14:20:07.718+0000] {warnings.py:110} WARNING - /home/***/.local/lib/python3.12/site-packages/***/task/task_runner/standard_task_runner.py:61: DeprecationWarning: This process (pid=461) is multi-threaded, use of fork() may lead to deadlocks in the child.
  pid = os.fork()

[2024-05-01T14:20:07.720+0000] {standard_task_runner.py:63} INFO - Started process 463 to run task
[2024-05-01T14:20:07.720+0000] {standard_task_runner.py:90} INFO - Running: ['***', 'tasks', 'run', 'create_vehicle_tables', 'create_***_db_task', 'manual__2024-05-01T14:15:00.135769+00:00', '--job-id', '53', '--raw', '--subdir', 'DAGS_FOLDER/create_table_dag.py', '--cfg-path', '/tmp/tmp9s1bt20i']
[2024-05-01T14:20:07.722+0000] {standard_task_runner.py:91} INFO - Job 53: Subtask create_***_db_task
[2024-05-01T14:20:07.816+0000] {task_command.py:426} INFO - Running <TaskInstance: create_vehicle_tables.create_airflow_db_task manual__2024-05-01T14:15:00.135769+00:00 [running]> on host cab22781d943
[2024-05-01T14:20:08.035+0000] {taskinstance.py:2644} INFO - Exporting env vars: AIRFLOW_CTX_DAG_OWNER='GetachewAbebe' AIRFLOW_CTX_DAG_ID='create_vehicle_tables' AIRFLOW_CTX_TASK_ID='create_***_db_task' AIRFLOW_CTX_EXECUTION_DATE='2024-05-01T14:15:00.135769+00:00' AIRFLOW_CTX_TRY_NUMBER='2' AIRFLOW_CTX_DAG_RUN_ID='manual__2024-05-01T14:15:00.135769+00:00'
[2024-05-01T14:20:08.036+0000] {taskinstance.py:430} INFO - ::endgroup::
[2024-05-01T14:20:08.038+0000] {taskinstance.py:441} INFO - ::group::Post task execution logs
[2024-05-01T14:20:08.038+0000] {taskinstance.py:2890} ERROR - Task failed with exception
Traceback (most recent call last):
  File "/home/airflow/.local/lib/python3.12/site-packages/airflow/models/taskinstance.py", line 465, in _execute_task
    result = _execute_callable(context=context, **execute_callable_kwargs)
             ^^^^^^^^^^^^^^^^^^^^^^^^^^^^^^^^^^^^^^^^^^^^^^^^^^^^^^^^^^^^^
  File "/home/airflow/.local/lib/python3.12/site-packages/airflow/models/taskinstance.py", line 432, in _execute_callable
    return execute_callable(context=context, **execute_callable_kwargs)
           ^^^^^^^^^^^^^^^^^^^^^^^^^^^^^^^^^^^^^^^^^^^^^^^^^^^^^^^^^^^^
  File "/home/airflow/.local/lib/python3.12/site-packages/airflow/models/baseoperator.py", line 400, in wrapper
    return func(self, *args, **kwargs)
           ^^^^^^^^^^^^^^^^^^^^^^^^^^^
  File "/home/airflow/.local/lib/python3.12/site-packages/airflow/operators/python.py", line 235, in execute
    return_value = self.execute_callable()
                   ^^^^^^^^^^^^^^^^^^^^^^^
  File "/home/airflow/.local/lib/python3.12/site-packages/airflow/operators/python.py", line 252, in execute_callable
    return self.python_callable(*self.op_args, **self.op_kwargs)
           ^^^^^^^^^^^^^^^^^^^^^^^^^^^^^^^^^^^^^^^^^^^^^^^^^^^^^
  File "/opt/airflow/dags/create_table_dag.py", line 37, in execute_sql_script
    with open(script_path, 'r') as script_file:
         ^^^^^^^^^^^^^^^^^^^^^^
FileNotFoundError: [Errno 2] No such file or directory: './scripts/create_database.sql'
[2024-05-01T14:20:08.048+0000] {taskinstance.py:1205} INFO - Marking task as UP_FOR_RETRY. dag_id=create_vehicle_tables, task_id=create_***_db_task, execution_date=20240501T141500, start_date=20240501T142007, end_date=20240501T142008
[2024-05-01T14:20:08.091+0000] {standard_task_runner.py:110} ERROR - Failed to execute job 53 for task create_***_db_task ([Errno 2] No such file or directory: './scripts/create_database.sql'; 463)
[2024-05-01T14:20:08.103+0000] {local_task_job_runner.py:240} INFO - Task exited with return code 1
[2024-05-01T14:20:08.125+0000] {taskinstance.py:3482} INFO - 0 downstream tasks scheduled from follow-on schedule check
[2024-05-01T14:20:08.149+0000] {local_task_job_runner.py:222} INFO - ::endgroup::
