[2024-05-01T14:30:49.664+0000] {local_task_job_runner.py:120} INFO - ::group::Pre task execution logs
[2024-05-01T14:30:49.686+0000] {taskinstance.py:2073} INFO - Dependencies all met for dep_context=non-requeueable deps ti=<TaskInstance: create_vehicle_tables.create_airflow_db_task manual__2024-05-01T14:15:37.686362+00:00 [queued]>
[2024-05-01T14:30:49.693+0000] {taskinstance.py:2073} INFO - Dependencies all met for dep_context=requeueable deps ti=<TaskInstance: create_vehicle_tables.create_airflow_db_task manual__2024-05-01T14:15:37.686362+00:00 [queued]>
[2024-05-01T14:30:49.693+0000] {taskinstance.py:2303} INFO - Starting attempt 4 of 5
[2024-05-01T14:30:49.734+0000] {taskinstance.py:2327} INFO - Executing <Task(PythonOperator): create_airflow_db_task> on 2024-05-01 14:15:37.686362+00:00
[2024-05-01T14:30:49.741+0000] {warnings.py:110} WARNING - /home/***/.local/lib/python3.12/site-packages/***/task/task_runner/standard_task_runner.py:61: DeprecationWarning: This process (pid=616) is multi-threaded, use of fork() may lead to deadlocks in the child.
  pid = os.fork()

[2024-05-01T14:30:49.743+0000] {standard_task_runner.py:63} INFO - Started process 618 to run task
[2024-05-01T14:30:49.743+0000] {standard_task_runner.py:90} INFO - Running: ['***', 'tasks', 'run', 'create_vehicle_tables', 'create_***_db_task', 'manual__2024-05-01T14:15:37.686362+00:00', '--job-id', '60', '--raw', '--subdir', 'DAGS_FOLDER/create_table_dag.py', '--cfg-path', '/tmp/tmpv924p58s']
[2024-05-01T14:30:49.744+0000] {standard_task_runner.py:91} INFO - Job 60: Subtask create_***_db_task
[2024-05-01T14:30:49.854+0000] {task_command.py:426} INFO - Running <TaskInstance: create_vehicle_tables.create_airflow_db_task manual__2024-05-01T14:15:37.686362+00:00 [running]> on host cab22781d943
[2024-05-01T14:30:49.986+0000] {taskinstance.py:2644} INFO - Exporting env vars: AIRFLOW_CTX_DAG_OWNER='GetachewAbebe' AIRFLOW_CTX_DAG_ID='create_vehicle_tables' AIRFLOW_CTX_TASK_ID='create_***_db_task' AIRFLOW_CTX_EXECUTION_DATE='2024-05-01T14:15:37.686362+00:00' AIRFLOW_CTX_TRY_NUMBER='4' AIRFLOW_CTX_DAG_RUN_ID='manual__2024-05-01T14:15:37.686362+00:00'
[2024-05-01T14:30:49.987+0000] {taskinstance.py:430} INFO - ::endgroup::
[2024-05-01T14:30:49.988+0000] {taskinstance.py:441} INFO - ::group::Post task execution logs
[2024-05-01T14:30:49.988+0000] {taskinstance.py:2890} ERROR - Task failed with exception
Traceback (most recent call last):
  File "/home/airflow/.local/lib/python3.12/site-packages/airflow/models/taskinstance.py", line 465, in _execute_task
    result = _execute_callable(context=context, **execute_callable_kwargs)
             ^^^^^^^^^^^^^^^^^^^^^^^^^^^^^^^^^^^^^^^^^^^^^^^^^^^^^^^^^^^^^
  File "/home/airflow/.local/lib/python3.12/site-packages/airflow/models/taskinstance.py", line 432, in _execute_callable
    return execute_callable(context=context, **execute_callable_kwargs)
           ^^^^^^^^^^^^^^^^^^^^^^^^^^^^^^^^^^^^^^^^^^^^^^^^^^^^^^^^^^^^
  File "/home/airflow/.local/lib/python3.12/site-packages/airflow/models/baseoperator.py", line 400, in wrapper
    return func(self, *args, **kwargs)
           ^^^^^^^^^^^^^^^^^^^^^^^^^^^
  File "/home/airflow/.local/lib/python3.12/site-packages/airflow/operators/python.py", line 235, in execute
    return_value = self.execute_callable()
                   ^^^^^^^^^^^^^^^^^^^^^^^
  File "/home/airflow/.local/lib/python3.12/site-packages/airflow/operators/python.py", line 252, in execute_callable
    return self.python_callable(*self.op_args, **self.op_kwargs)
           ^^^^^^^^^^^^^^^^^^^^^^^^^^^^^^^^^^^^^^^^^^^^^^^^^^^^^
  File "/opt/airflow/dags/create_table_dag.py", line 37, in execute_sql_script
    with open(script_path, 'r') as script_file:
         ^^^^^^^^^^^^^^^^^^^^^^
FileNotFoundError: [Errno 2] No such file or directory: './scripts/create_database.sql'
[2024-05-01T14:30:49.996+0000] {taskinstance.py:1205} INFO - Marking task as UP_FOR_RETRY. dag_id=create_vehicle_tables, task_id=create_***_db_task, execution_date=20240501T141537, start_date=20240501T143049, end_date=20240501T143049
[2024-05-01T14:30:50.059+0000] {standard_task_runner.py:110} ERROR - Failed to execute job 60 for task create_***_db_task ([Errno 2] No such file or directory: './scripts/create_database.sql'; 618)
[2024-05-01T14:30:50.117+0000] {local_task_job_runner.py:240} INFO - Task exited with return code 1
[2024-05-01T14:30:50.182+0000] {taskinstance.py:3482} INFO - 0 downstream tasks scheduled from follow-on schedule check
[2024-05-01T14:30:50.224+0000] {local_task_job_runner.py:222} INFO - ::endgroup::
